Traceback (most recent call last):
  File "/home/collins/Param_test/initExperiment.py", line 27, in <module>
    os.makedirs(folder)
  File "/home/apps/anaconda3/lib/python3.7/os.py", line 221, in makedirs
    mkdir(name, mode)
FileExistsError: [Errno 17] File exists: '/home/collins/Simulation_Data/Wide_EIB_GABAALNPN_0.5/OdorA_High_Dur_6000_OdorDur_1000_Locust_A_5'
Traceback (most recent call last):
  File "/home/collins/Param_test/initExperiment.py", line 27, in <module>
    os.makedirs(folder)
  File "/home/apps/anaconda3/lib/python3.7/os.py", line 221, in makedirs
    mkdir(name, mode)
FileExistsError: [Errno 17] File exists: '/home/collins/Simulation_Data/Wide_EIB_GABAALNPN_0.5/OdorA_High_Dur_6000_OdorDur_1000_Locust_A_5'
Traceback (most recent call last):
  File "/home/collins/Param_test/initExperiment.py", line 27, in <module>
    os.makedirs(folder)
  File "/home/apps/anaconda3/lib/python3.7/os.py", line 221, in makedirs
    mkdir(name, mode)
FileExistsError: [Errno 17] File exists: '/home/collins/Simulation_Data/Wide_EIB_GABAALNPN_0.5/OdorA_High_Dur_6000_OdorDur_1000_Locust_A_5'
Traceback (most recent call last):
  File "/home/collins/Param_test/initExperiment.py", line 27, in <module>
    os.makedirs(folder)
  File "/home/apps/anaconda3/lib/python3.7/os.py", line 221, in makedirs
    mkdir(name, mode)
FileExistsError: [Errno 17] File exists: '/home/collins/Simulation_Data/Wide_EIB_GABAALNPN_0.5/OdorA_High_Dur_6000_OdorDur_1000_Locust_A_5'
srun: error: cn087: tasks 1,13,16,23: Exited with exit code 1
Traceback (most recent call last):
  File "/home/collins/Param_test/initExperiment.py", line 51, in <module>
    call(['python','/home/collins/Param_test/antennalLobe.py',str(i), locust_path, protocol_path, sys.argv[5], folder, sys.argv[6]])
  File "/home/apps/anaconda3/lib/python3.7/subprocess.py", line 323, in call
    with Popen(*popenargs, **kwargs) as p:
  File "/home/apps/anaconda3/lib/python3.7/subprocess.py", line 775, in __init__
    restore_signals, start_new_session)
  File "/home/apps/anaconda3/lib/python3.7/subprocess.py", line 1453, in _execute_child
    restore_signals, start_new_session, preexec_fn)
OSError: [Errno 12] Cannot allocate memory
srun: error: cn087: task 34: Exited with exit code 1
Traceback (most recent call last):
  File "/home/collins/Param_test/receptorLayer.py", line 102, in <module>
    random_normal = np.random.normal(size=orns.shape)
  File "mtrand.pyx", line 1484, in numpy.random.mtrand.RandomState.normal
  File "_common.pyx", line 558, in numpy.random._common.cont
MemoryError: Unable to allocate 4.47 GiB for an array with shape (1000, 600000) and data type float64
Traceback (most recent call last):
  File "/home/collins/Param_test/receptorLayer.py", line 102, in <module>
    random_normal = np.random.normal(size=orns.shape)
  File "mtrand.pyx", line 1484, in numpy.random.mtrand.RandomState.normal
  File "_common.pyx", line 558, in numpy.random._common.cont
MemoryError: Unable to allocate 4.47 GiB for an array with shape (1000, 600000) and data type float64
slurmstepd: error: *** JOB 34364 ON cn087 CANCELLED AT 2020-02-18T12:36:10 ***
slurmstepd: error: *** STEP 34364.0 ON cn087 CANCELLED AT 2020-02-18T12:36:10 ***
